
Downloading readme: 100%|██████████████████████████████████| 10.5k/10.5k [00:00<00:00, 71.1kB/s]
Traceback (most recent call last):
  File "/home/abhi98m/anaconda3/envs/taylordiff/lib/python3.12/site-packages/huggingface_hub/utils/_errors.py", line 304, in hf_raise_for_status
    response.raise_for_status()
  File "/home/abhi98m/anaconda3/envs/taylordiff/lib/python3.12/site-packages/requests/models.py", line 1024, in raise_for_status
    raise HTTPError(http_error_msg, response=self)
requests.exceptions.HTTPError: 401 Client Error: Unauthorized for url: https://huggingface.co/google/gemma-2b/resolve/main/config.json
The above exception was the direct cause of the following exception:
Traceback (most recent call last):
  File "/home/abhi98m/anaconda3/envs/taylordiff/lib/python3.12/site-packages/transformers/utils/hub.py", line 402, in cached_file
    resolved_file = hf_hub_download(
                    ^^^^^^^^^^^^^^^^
  File "/home/abhi98m/anaconda3/envs/taylordiff/lib/python3.12/site-packages/huggingface_hub/utils/_deprecation.py", line 101, in inner_f
    return f(*args, **kwargs)
           ^^^^^^^^^^^^^^^^^^
  File "/home/abhi98m/anaconda3/envs/taylordiff/lib/python3.12/site-packages/huggingface_hub/utils/_validators.py", line 114, in _inner_fn
    return fn(*args, **kwargs)
           ^^^^^^^^^^^^^^^^^^^
  File "/home/abhi98m/anaconda3/envs/taylordiff/lib/python3.12/site-packages/huggingface_hub/file_download.py", line 1240, in hf_hub_download
    return _hf_hub_download_to_cache_dir(
           ^^^^^^^^^^^^^^^^^^^^^^^^^^^^^^
  File "/home/abhi98m/anaconda3/envs/taylordiff/lib/python3.12/site-packages/huggingface_hub/file_download.py", line 1347, in _hf_hub_download_to_cache_dir
    _raise_on_head_call_error(head_call_error, force_download, local_files_only)
  File "/home/abhi98m/anaconda3/envs/taylordiff/lib/python3.12/site-packages/huggingface_hub/file_download.py", line 1854, in _raise_on_head_call_error
    raise head_call_error
  File "/home/abhi98m/anaconda3/envs/taylordiff/lib/python3.12/site-packages/huggingface_hub/file_download.py", line 1751, in _get_metadata_or_catch_error
    metadata = get_hf_file_metadata(
               ^^^^^^^^^^^^^^^^^^^^^
  File "/home/abhi98m/anaconda3/envs/taylordiff/lib/python3.12/site-packages/huggingface_hub/utils/_validators.py", line 114, in _inner_fn
    return fn(*args, **kwargs)
           ^^^^^^^^^^^^^^^^^^^
  File "/home/abhi98m/anaconda3/envs/taylordiff/lib/python3.12/site-packages/huggingface_hub/file_download.py", line 1673, in get_hf_file_metadata
    r = _request_wrapper(
        ^^^^^^^^^^^^^^^^^
  File "/home/abhi98m/anaconda3/envs/taylordiff/lib/python3.12/site-packages/huggingface_hub/file_download.py", line 376, in _request_wrapper
    response = _request_wrapper(
               ^^^^^^^^^^^^^^^^^
  File "/home/abhi98m/anaconda3/envs/taylordiff/lib/python3.12/site-packages/huggingface_hub/file_download.py", line 400, in _request_wrapper
    hf_raise_for_status(response)
  File "/home/abhi98m/anaconda3/envs/taylordiff/lib/python3.12/site-packages/huggingface_hub/utils/_errors.py", line 321, in hf_raise_for_status
    raise GatedRepoError(message, response) from e
huggingface_hub.utils._errors.GatedRepoError: 401 Client Error. (Request ID: Root=1-66be0ef5-713fa923791275606cb947ea;3fdd6c57-5847-467f-9a8a-ad2fb1f1c1f0)
Cannot access gated repo for url https://huggingface.co/google/gemma-2b/resolve/main/config.json.
Access to model google/gemma-2b is restricted. You must be authenticated to access it.
The above exception was the direct cause of the following exception:
Traceback (most recent call last):
  File "/home/ubuntu/rbg-group/abhi98m/taylordiff/main.py", line 18, in <module>
    main()
  File "/home/ubuntu/rbg-group/abhi98m/taylordiff/main.py", line 12, in main
    train_dataset, val_dataset, vocab_size = load_and_preprocess_data(config)
                                             ^^^^^^^^^^^^^^^^^^^^^^^^^^^^^^^^
  File "/home/ubuntu/rbg-group/abhi98m/taylordiff/src/data.py", line 6, in load_and_preprocess_data
    tokenizer = AutoTokenizer.from_pretrained(config['tokenizer']['name'])
                ^^^^^^^^^^^^^^^^^^^^^^^^^^^^^^^^^^^^^^^^^^^^^^^^^^^^^^^^^^
  File "/home/abhi98m/anaconda3/envs/taylordiff/lib/python3.12/site-packages/transformers/models/auto/tokenization_auto.py", line 854, in from_pretrained
    config = AutoConfig.from_pretrained(
             ^^^^^^^^^^^^^^^^^^^^^^^^^^^
  File "/home/abhi98m/anaconda3/envs/taylordiff/lib/python3.12/site-packages/transformers/models/auto/configuration_auto.py", line 976, in from_pretrained
    config_dict, unused_kwargs = PretrainedConfig.get_config_dict(pretrained_model_name_or_path, **kwargs)
                                 ^^^^^^^^^^^^^^^^^^^^^^^^^^^^^^^^^^^^^^^^^^^^^^^^^^^^^^^^^^^^^^^^^^^^^^^^^
  File "/home/abhi98m/anaconda3/envs/taylordiff/lib/python3.12/site-packages/transformers/configuration_utils.py", line 632, in get_config_dict
    config_dict, kwargs = cls._get_config_dict(pretrained_model_name_or_path, **kwargs)
                          ^^^^^^^^^^^^^^^^^^^^^^^^^^^^^^^^^^^^^^^^^^^^^^^^^^^^^^^^^^^^^
  File "/home/abhi98m/anaconda3/envs/taylordiff/lib/python3.12/site-packages/transformers/configuration_utils.py", line 689, in _get_config_dict
    resolved_config_file = cached_file(
                           ^^^^^^^^^^^^
  File "/home/abhi98m/anaconda3/envs/taylordiff/lib/python3.12/site-packages/transformers/utils/hub.py", line 420, in cached_file
    raise EnvironmentError(
OSError: You are trying to access a gated repo.
Make sure to have access to it at https://huggingface.co/google/gemma-2b.
401 Client Error. (Request ID: Root=1-66be0ef5-713fa923791275606cb947ea;3fdd6c57-5847-467f-9a8a-ad2fb1f1c1f0)
Cannot access gated repo for url https://huggingface.co/google/gemma-2b/resolve/main/config.json.
Access to model google/gemma-2b is restricted. You must be authenticated to access it.